Workbook
Name Cat: '[1]SITE SHEET'!$V$4:$V$13
Name Cat: '[2]SITE SHEET'!$V$4:$V$13
Name Category: [1]States!$H$5:$H$13
Name Category: [2]States!$H$5:$H$13
Name CostShare: [1]States!$K$4:$K$8
Name CostShare: [2]States!$K$4:$K$8
Name Disaster_Type: [1]States!$J$5:$J$6
Name Disaster_Type: [2]States!$J$5:$J$6
Name FEMACC: FEMAcostcodes!$A$4:$A$968
Name FEMACC: [2]CODES!#REF!
Name FEMACCD: FEMAcostcodes!$I$4:$I$968
Name FEMACCD: [2]CODES!#REF!
Name FEMACCR: FEMAcostcodes!$D$4:$D$968
Name FEMACCR: [2]CODES!#REF!
Name FEMACCU: FEMAcostcodes!$C$4:$C$968
Name FEMACCU: [2]CODES!#REF!
Name femacode: FEMAcostcodes!$I$620:$I$961
Name femacode: [2]CODES!#REF!
Name FEMAEC: FEMAcostcodes!$F$620:$F$961
Name FEMAEC: [2]CODES!#REF!
Name FEMAECODE: FEMAcostcodes!$A$620:$A$962
Name FEMAECODE: [2]CODES!#REF!
Name FEMAEHP: FEMAcostcodes!$F$620:$F$961
Name FEMAEHP: [2]CODES!#REF!
Name FEMAEN: FEMAcostcodes!$E$620:$E$961
Name FEMAEN: [2]CODES!#REF!
Name FEMAER: FEMAcostcodes!$D$620:$D$961
Name FEMAER: [2]CODES!#REF!
Name FEMAES: FEMAcostcodes!$D$620:$D$961
Name FEMAES: [2]CODES!#REF!
Name OPERATOR: OFFSET('[1]PAYROLL DATA'!$B$10,0,0,COUNTA('[1]PAYROLL DATA'!$B:$B),1)
Name OPERATOR: OFFSET('[2]PAYROLL DATA'!$B$10,0,0,COUNTA('[2]PAYROLL DATA'!$B:$B),1)
Name OTTYPE: '[3]PAYROLL DATA'!#REF!
Name OTTYPE: '[4]PAYROLL DATA'!#REF!
Name PAYROLLDATA: OFFSET('[1]PAYROLL DATA'!$B$9,0,0,COUNTA('[1]PAYROLL DATA'!$B:$B),1)
Name PAYROLLDATA: OFFSET('[2]PAYROLL DATA'!$B$9,0,0,COUNTA('[2]PAYROLL DATA'!$B:$B),1)
Name ProjectType: [1]Utility!$AW$8:$AW$10
Name ProjectType: [2]Utility!$AW$8:$AW$10
Name States: [1]States!$A$1:$A$52
Name States: [2]States!$A$1:$A$52
Name Yes_No: [1]States!$I$5:$I$6
Name Yes_No: [2]States!$I$5:$I$6

Sheet Estimate
F1: Category Summary
F2: A | G2: =SUMIF($A$11:$A$84,F2,$G$11:$G$84) -> 0
F3: B | G3: =SUMIF($A$11:$A$84,F3,$G$11:$G$84) -> 0
F4: C | G4: =SUMIF($A$11:$A$84,F4,$G$11:$G$84) -> 0
F5: D | G5: =SUMIF($A$11:$A$84,F5,$G$11:$G$84) -> 0
F6: E | G6: =SUMIF($A$11:$A$84,F6,$G$11:$G$84) -> 0
F7: TOTAL | G7: =SUM(G2:G6) -> 0
A10: Category | B10: Cost Code | C10: Description | D10: Unit Cost | E10: Unit | F10: Quantity | G10: Sub Total | H10: Comments | LZ10: Cost Code | MA10: Unit | MB10: Description | MC10: Unit Cost | MD10: Comments
C11: =IF(ISBLANK(B11)," ",VLOOKUP(B11,LZ11:MD1235,3,FALSE)) | D11: =IF(ISBLANK(B11)," ",VLOOKUP(B11,LZ11:MD1235,4,FALSE)) | E11: =IF(ISBLANK(B11)," ",VLOOKUP(B11,LZ11:MD1235,2,FALSE)) | G11: =IF(ISERROR(D11*F11)," ",D11*F11) | LZ11: 0 | MA11: LS | MB11: ****************************************** create line | MC11: $ 0.00
C12: =IF(ISBLANK(B12)," ",VLOOKUP(B12,LZ12:MD1236,3,FALSE)) | D12: =IF(ISBLANK(B12)," ",VLOOKUP(B12,LZ12:MD1236,4,FALSE)) | E12: =IF(ISBLANK(B12)," ",VLOOKUP(B12,LZ12:MD1236,2,FALSE)) | G12: =IF(ISERROR(D12*F12)," ",D12*F12) | LZ12: 852 | MA12: LS | MB12: STATE MANAGEMENT COSTS | MC12: $ 0.00
C13: =IF(ISBLANK(B13)," ",VLOOKUP(B13,LZ13:MD1237,3,FALSE)) | D13: =IF(ISBLANK(B13)," ",VLOOKUP(B13,LZ13:MD1237,4,FALSE)) | E13: =IF(ISBLANK(B13)," ",VLOOKUP(B13,LZ13:MD1237,2,FALSE)) | G13: =IF(ISERROR(D13*F13)," ",D13*F13) | MB13: State Management Costs
C14: =IF(ISBLANK(B14)," ",VLOOKUP(B14,LZ14:MD1238,3,FALSE)) | D14: =IF(ISBLANK(B14)," ",VLOOKUP(B14,LZ14:MD1238,4,FALSE)) | E14: =IF(ISBLANK(B14)," ",VLOOKUP(B14,LZ14:MD1238,2,FALSE)) | G14: =IF(ISERROR(D14*F14)," ",D14*F14) | LZ14: 909 | MA14: LS | MB14: MITIGATION | MC14: $ 0.00
C15: =IF(ISBLANK(B15)," ",VLOOKUP(B15,LZ15:MD1239,3,FALSE)) | D15: =IF(ISBLANK(B15)," ",VLOOKUP(B15,LZ15:MD1239,4,FALSE)) | E15: =IF(ISBLANK(B15)," ",VLOOKUP(B15,LZ15:MD1239,2,FALSE)) | G15: =IF(ISERROR(D15*F15)," ",D15*F15) | MB15: Mitigation
C16: =IF(ISBLANK(B16)," ",VLOOKUP(B16,LZ16:MD1240,3,FALSE)) | D16: =IF(ISBLANK(B16)," ",VLOOKUP(B16,LZ16:MD1240,4,FALSE)) | E16: =IF(ISBLANK(B16)," ",VLOOKUP(B16,LZ16:MD1240,2,FALSE)) | G16: =IF(ISERROR(D16*F16)," ",D16*F16) | LZ16: 1001 | MA16: TON | MB16: DEBRIS (SEDIMENTS, CONCENTRATED) | MC16: $ 0.00
C17: =IF(ISBLANK(B17)," ",VLOOKUP(B17,LZ17:MD1241,3,FALSE)) | D17: =IF(ISBLANK(B17)," ",VLOOKUP(B17,LZ17:MD1241,4,FALSE)) | E17: =IF(ISBLANK(B17)," ",VLOOKUP(B17,LZ17:MD1241,2,FALSE)) | G17: =IF(ISERROR(D17*F17)," ",D17*F17) | MB17: Debris, sediments, concentrated
C18: =IF(ISBLANK(B18)," ",VLOOKUP(B18,LZ18:MD1242,3,FALSE)) | D18: =IF(ISBLANK(B18)," ",VLOOKUP(B18,LZ18:MD1242,4,FALSE)) | E18: =IF(ISBLANK(B18)," ",VLOOKUP(B18,LZ18:MD1242,2,FALSE)) | G18: =IF(ISERROR(D18*F18)," ",D18*F18) | LZ18: 1002 | MA18: TON | MB18: DEBRIS, (SEDIMENTS, SCATTERED) | MC18: $ 0.00
C19: =IF(ISBLANK(B19)," ",VLOOKUP(B19,LZ19:MD1243,3,FALSE)) | D19: =IF(ISBLANK(B19)," ",VLOOKUP(B19,LZ19:MD1243,4,FALSE)) | E19: =IF(ISBLANK(B19)," ",VLOOKUP(B19,LZ19:MD1243,2,FALSE)) | G19: =IF(ISERROR(D19*F19)," ",D19*F19) | MB19: Debris, (sedimetns, scattered)
C20: =IF(ISBLANK(B20)," ",VLOOKUP(B20,LZ20:MD1244,3,FALSE)) | D20: =IF(ISBLANK(B20)," ",VLOOKUP(B20,LZ20:MD1244,4,FALSE)) | E20: =IF(ISBLANK(B20)," ",VLOOKUP(B20,LZ20:MD1244,2,FALSE)) | G20: =IF(ISERROR(D20*F20)," ",D20*F20) | LZ20: 1003 | MA20: TON | MB20: DEBRIS (PERSONAL PROPERTY CURB) | MC20: $ 0.00
C21: =IF(ISBLANK(B21)," ",VLOOKUP(B21,LZ21:MD1245,3,FALSE)) | D21: =IF(ISBLANK(B21)," ",VLOOKUP(B21,LZ21:MD1245,4,FALSE)) | E21: =IF(ISBLANK(B21)," ",VLOOKUP(B21,LZ21:MD1245,2,FALSE)) | G21: =IF(ISERROR(D21*F21)," ",D21*F21) | MB21: Should not be limited to private residences. Labor and equipment required
C22: =IF(ISBLANK(B22)," ",VLOOKUP(B22,LZ22:MD1246,3,FALSE)) | D22: =IF(ISBLANK(B22)," ",VLOOKUP(B22,LZ22:MD1246,4,FALSE)) | E22: =IF(ISBLANK(B22)," ",VLOOKUP(B22,LZ22:MD1246,2,FALSE)) | G22: =IF(ISERROR(D22*F22)," ",D22*F22) | MB22: to remove damaged personal property. Property such as furniture or appliances, from curb side of private residences. Does not include dump
C23: =IF(ISBLANK(B23)," ",VLOOKUP(B23,LZ23:MD1247,3,FALSE)) | D23: =IF(ISBLANK(B23)," ",VLOOKUP(B23,LZ23:MD1247,4,FALSE)) | E23: =IF(ISBLANK(B23)," ",VLOOKUP(B23,LZ23:MD1247,2,FALSE)) | G23: =IF(ISERROR(D23*F23)," ",D23*F23) | MB23: charges.
C24: =IF(ISBLANK(B24)," ",VLOOKUP(B24,LZ24:MD1248,3,FALSE)) | D24: =IF(ISBLANK(B24)," ",VLOOKUP(B24,LZ24:MD1248,4,FALSE)) | E24: =IF(ISBLANK(B24)," ",VLOOKUP(B24,LZ24:MD1248,2,FALSE)) | G24: =IF(ISERROR(D24*F24)," ",D24*F24) | LZ24: 1004 | MA24: TON | MB24: DEBRIS (TREES & LIMBS, CONCENTRATED) | MC24: $ 0.00
C25: =IF(ISBLANK(B25)," ",VLOOKUP(B25,LZ25:MD1249,3,FALSE)) | D25: =IF(ISBLANK(B25)," ",VLOOKUP(B25,LZ25:MD1249,4,FALSE)) | E25: =IF(ISBLANK(B25)," ",VLOOKUP(B25,LZ25:MD1249,2,FALSE)) | G25: =IF(ISERROR(D25*F25)," ",D25*F25) | MB25: Broken trees and limbs that have been picked up and brought to an
C26: =IF(ISBLANK(B26)," ",VLOOKUP(B26,LZ26:MD1250,3,FALSE)) | D26: =IF(ISBLANK(B26)," ",VLOOKUP(B26,LZ26:MD1250,4,FALSE)) | E26: =IF(ISBLANK(B26)," ",VLOOKUP(B26,LZ26:MD1250,2,FALSE)) | G26: =IF(ISERROR(D26*F26)," ",D26*F26) | MB26: assembly area. May also include localized heavy tree damage in a park or
C27: =IF(ISBLANK(B27)," ",VLOOKUP(B27,LZ27:MD1251,3,FALSE)) | D27: =IF(ISBLANK(B27)," ",VLOOKUP(B27,LZ27:MD1251,4,FALSE)) | E27: =IF(ISBLANK(B27)," ",VLOOKUP(B27,LZ27:MD1251,2,FALSE)) | G27: =IF(ISERROR(D27*F27)," ",D27*F27) | MB27: other location,
C28: =IF(ISBLANK(B28)," ",VLOOKUP(B28,LZ28:MD1252,3,FALSE)) | D28: =IF(ISBLANK(B28)," ",VLOOKUP(B28,LZ28:MD1252,4,FALSE)) | E28: =IF(ISBLANK(B28)," ",VLOOKUP(B28,LZ28:MD1252,2,FALSE)) | G28: =IF(ISERROR(D28*F28)," ",D28*F28) | LZ28: 1005 | MA28: TON | MB28: DEBRIS (TREES & LIMBS, SCATTERED) | MC28: $ 0.00
C29: =IF(ISBLANK(B29)," ",VLOOKUP(B29,LZ29:MD1253,3,FALSE)) | D29: =IF(ISBLANK(B29)," ",VLOOKUP(B29,LZ29:MD1253,4,FALSE)) | E29: =IF(ISBLANK(B29)," ",VLOOKUP(B29,LZ29:MD1253,2,FALSE)) | G29: =IF(ISERROR(D29*F29)," ",D29*F29) | MB29: Debris, (trees & limbs, scattered)
C30: =IF(ISBLANK(B30)," ",VLOOKUP(B30,LZ30:MD1254,3,FALSE)) | D30: =IF(ISBLANK(B30)," ",VLOOKUP(B30,LZ30:MD1254,4,FALSE)) | E30: =IF(ISBLANK(B30)," ",VLOOKUP(B30,LZ30:MD1254,2,FALSE)) | G30: =IF(ISERROR(D30*F30)," ",D30*F30) | LZ30: 1010 | MA30: CY | MB30: DEBRIS, (SEDIMENTS, CONCENTRATED) | MC30: $ 3.00
C31: =IF(ISBLANK(B31)," ",VLOOKUP(B31,LZ31:MD1255,3,FALSE)) | D31: =IF(ISBLANK(B31)," ",VLOOKUP(B31,LZ31:MD1255,4,FALSE)) | E31: =IF(ISBLANK(B31)," ",VLOOKUP(B31,LZ31:MD1255,2,FALSE)) | G31: =IF(ISERROR(D31*F31)," ",D31*F31) | MB31: Removal of concentrated sediment
C32: =IF(ISBLANK(B32)," ",VLOOKUP(B32,LZ32:MD1256,3,FALSE)) | D32: =IF(ISBLANK(B32)," ",VLOOKUP(B32,LZ32:MD1256,4,FALSE)) | E32: =IF(ISBLANK(B32)," ",VLOOKUP(B32,LZ32:MD1256,2,FALSE)) | G32: =IF(ISERROR(D32*F32)," ",D32*F32) | LZ32: 1011 | MA32: CY | MB32: DEBRIS, (SEDIMENTS, SCATTERED) | MC32: $ 4.00
C33: =IF(ISBLANK(B33)," ",VLOOKUP(B33,LZ33:MD1257,3,FALSE)) | D33: =IF(ISBLANK(B33)," ",VLOOKUP(B33,LZ33:MD1257,4,FALSE)) | E33: =IF(ISBLANK(B33)," ",VLOOKUP(B33,LZ33:MD1257,2,FALSE)) | G33: =IF(ISERROR(D33*F33)," ",D33*F33) | MB33: Removal of scattered sediments
C34: =IF(ISBLANK(B34)," ",VLOOKUP(B34,LZ34:MD1258,3,FALSE)) | D34: =IF(ISBLANK(B34)," ",VLOOKUP(B34,LZ34:MD1258,4,FALSE)) | E34: =IF(ISBLANK(B34)," ",VLOOKUP(B34,LZ34:MD1258,2,FALSE)) | G34: =IF(ISERROR(D34*F34)," ",D34*F34) | LZ34: 1012 | MA34: CY | MB34: DEBRIS (PERSONAL PROPERTY CURB) | MC34: $ 3.50
C35: =IF(ISBLANK(B35)," ",VLOOKUP(B35,LZ35:MD1259,3,FALSE)) | D35: =IF(ISBLANK(B35)," ",VLOOKUP(B35,LZ35:MD1259,4,FALSE)) | E35: =IF(ISBLANK(B35)," ",VLOOKUP(B35,LZ35:MD1259,2,FALSE)) | G35: =IF(ISERROR(D35*F35)," ",D35*F35) | MB35: Should not be limited to private residences. Labor and equipment required
C36: =IF(ISBLANK(B36)," ",VLOOKUP(B36,LZ36:MD1260,3,FALSE)) | D36: =IF(ISBLANK(B36)," ",VLOOKUP(B36,LZ36:MD1260,4,FALSE)) | E36: =IF(ISBLANK(B36)," ",VLOOKUP(B36,LZ36:MD1260,2,FALSE)) | G36: =IF(ISERROR(D36*F36)," ",D36*F36) | MB36: to remove damaged personal property, such as furniture or appliances,
C37: =IF(ISBLANK(B37)," ",VLOOKUP(B37,LZ37:MD1261,3,FALSE)) | D37: =IF(ISBLANK(B37)," ",VLOOKUP(B37,LZ37:MD1261,4,FALSE)) | E37: =IF(ISBLANK(B37)," ",VLOOKUP(B37,LZ37:MD1261,2,FALSE)) | G37: =IF(ISERROR(D37*F37)," ",D37*F37) | MB37: from curb side of private residences. Does not include dump charges.
C38: =IF(ISBLANK(B38)," ",VLOOKUP(B38,LZ38:MD1262,3,FALSE)) | D38: =IF(ISBLANK(B38)," ",VLOOKUP(B38,LZ38:MD1262,4,FALSE)) | E38: =IF(ISBLANK(B38)," ",VLOOKUP(B38,LZ38:MD1262,2,FALSE)) | G38: =IF(ISERROR(D38*F38)," ",D38*F38) | MB38: assembly area. May also include localized heavy tree damage in a park or
C39: =IF(ISBLANK(B39)," ",VLOOKUP(B39,LZ39:MD1263,3,FALSE)) | D39: =IF(ISBLANK(B39)," ",VLOOKUP(B39,LZ39:MD1263,4,FALSE)) | E39: =IF(ISBLANK(B39)," ",VLOOKUP(B39,LZ39:MD1263,2,FALSE)) | G39: =IF(ISERROR(D39*F39)," ",D39*F39) | MB39: other location,
C40: =IF(ISBLANK(B40)," ",VLOOKUP(B40,LZ40:MD1264,3,FALSE)) | D40: =IF(ISBLANK(B40)," ",VLOOKUP(B40,LZ40:MD1264,4,FALSE)) | E40: =IF(ISBLANK(B40)," ",VLOOKUP(B40,LZ40:MD1264,2,FALSE)) | G40: =IF(ISERROR(D40*F40)," ",D40*F40) | LZ40: 1005 | MA40: TON | MB40: DEBRIS (TREES & LIMBS, SCATTERED) | MC40: $ 0.00
C41: =IF(ISBLANK(B41)," ",VLOOKUP(B41,LZ41:MD1265,3,FALSE)) | D41: =IF(ISBLANK(B41)," ",VLOOKUP(B41,LZ41:MD1265,4,FALSE)) | E41: =IF(ISBLANK(B41)," ",VLOOKUP(B41,LZ41:MD1265,2,FALSE)) | G41: =IF(ISERROR(D41*F41)," ",D41*F41) | MB41: Debris, (trees & limbs, scattered)
C42: =IF(ISBLANK(B42)," ",VLOOKUP(B42,LZ42:MD1266,3,FALSE)) | D42: =IF(ISBLANK(B42)," ",VLOOKUP(B42,LZ42:MD1266,4,FALSE)) | E42: =IF(ISBLANK(B42)," ",VLOOKUP(B42,LZ42:MD1266,2,FALSE)) | G42: =IF(ISERROR(D42*F42)," ",D42*F42) | LZ42: 1010 | MA42: CY | MB42: DEBRIS, (SEDIMENTS, CONCENTRATED) | MC42: $ 3.00
...

Sheet Summary Sheet
A1: DEPARTMENT OF HOMELAND SECURITY
A2: FEDERAL EMERGENCY MANAGEMENT
A3: PRELIMINARY DAMAGE ASSESSMENT SUMMARY
A5: Part 1 - Applicant Information
A6: County | D6: Potential Applicant/Public Entity | G6: Name of Local Contact | J6: Contact Phone #
A7: Bosque | D7: Multiple | G7: Multiple (individual sheets) | J7: (various)
A8: Population | C8: Total Budget | E8: Maintenance Budget | G8: Insured | J8: Date
G9: Needs Mitigation
A10: Part II - Site Estimate Summary
A11: Category | C11: Critical Facilities and Other Damages | E11: Inspected | G11: Projected | I11: Total
E12: # of Sites | F12: Cost | G12: # of Sites | H12: Cost | I12: # of Sites | J12: Total Cost
A13: A | B13: Debris | E13: 1 | F13: ='Valley Mills'!K20 -> 3080 | I13: =E13+G13 -> 1 | J13: =F13+H13 -> 3080
A14: B | B14: Prot. Measures | I14: =E14+G14 -> 0 | J14: =F14+H14 -> 0
B15: Cat A & B Emergency work sub-total | J15: =J13+J14 -> 3080
A17: C | B17: Roads and Bridges | C17: Bridge | I17: =E17+G17 -> 0
C18: Roadway | E18: 9 | F18: ='Bosque Co'!K20+'Bosque Co'!K30+'Bosque Co'!K40+'Bosque Co'!K50+'Bosque Co (2)'!K20+Clifton!K20+Clifton!K30+Clifton!K40+Clifton!K50 -> 165925 | G18: 4 | H18: =9000+500+1200+10500 -> 21200 | I18: =E18+G18 -> 13 | J18: =F18+H18 -> 187125
C19: Aggregate surface loss only | I19: =E19+G19 -> 0 | J19: =F19+H19 -> 0
B20: Cat C Sub-total | J20: =J17+J18+J19 -> 187125
A22: D | B22: Water Control Facilities | C22: Dam | E22: 1 | F22: ='Clifton(2)'!K20 -> 22500 | I22: =E22+G22 -> 1 | J22: =F22+H22 -> 22500
C23: Levee | I23: =E23+G23 -> 0 | J23: =F23+H23 -> 0
C24: Drainage Channel | I24: =E24+G24 -> 0
B25: Cat D Sub-total | J25: =J22+J23+J24 -> 22500
A27: E | B27: Public Buildings | I27: =E27+G27 -> 0
D28: Contents | I28: =E28+G28 -> 0 | J28: =F28+H28 -> 0
I29: =E29+G29 -> 0 | J29: =F29+H29 -> 0
B30: Cat E Sub-total | J30: =J27+J28+J29 -> 0
A32: F | B32: Public Utilities | C32: Water Treatment | I32: =E32+G32 -> 0 | J32: =F32+H32 -> 0
C33: Water Utility | I33: =E33+G33 -> 0 | J33: =F33+H33 -> 0
C34: Sewage Treatment | I34: =E34+G34 -> 0 | J34: =F34+H34 -> 0
B35: Cat F Sub-total | J35: =J32+J33+J34 -> 0
A37: G | B37: Other Recreation | C37: Railroad | I37: =E37+G37 -> 0 | J37: =F37+H37 -> 0
C38: Fence | I38: =E38+G38 -> 0 | J38: =F38+H38 -> 0
I39: =E39+G39 -> 0
B40: Cat G Sub-total | J40: =J37+J38+J39 -> 0
A42: Emergency and Permanent Work Total
H44: GRAND TOTAL | J44: =J15+J20+J25+J30+J35+J40 -> 212705
A46: Part lll - Disaster Impacts (Use separate sheets if necessary) | L46: Restricted access for emergency responder vehicles, public school transportation and local residence.
A47: A. General Impact | L47: Prevailing damages restricting access proposes a threat to public health and safety
A48: 1. Briefly describe damages which constitute a health and safety hazard to the general public.
L49: Emergency vehicles, school bus and postal services unable to perform mission due to road and bridge wash out.
...

Sheet Bosque Co
A1: Federal Emergency Management Agency | L1: Date
A2: Preliminary Damage Assessment Site Estimate | L2: 42557
A3: Part 1 - Applicant Information
A4: County | C4: Name Of Applicant | G4: Name Of Local Contact | L4: Contact Phone #
A5: Bosque | C5: Bosque County | G5: Tim Jeske | L5: 254-230-6622
A6: Part 2 - Site Information
A7: Key For Damage Category (Use appropriate letters in the "category" blocks below)
B8: a. Debris Removal | E8: d. Water Control Facilities | I8: g. Other Recreation
B9: b. Protective Measures | E9: e. Public Buildings
B10: c. Roads And Bridges | E10: f. Public Utilities
A11: Site No. | B11: Category | C11: Location (Use map location, address, etc.): | G11: CR-3105 | L11: GPS
A12: 1 | B12: C | L12: 31.854218
L13: -97.618797
A14: Description Of Damage
A15: Culvert with headwall collapsed on downstream end of cmp. Hand stacked headwall with concrete top. Minor damage on inlet end of cmp.
A19: Impact: | B19: Minor | H19: % Complete | K19: Cost Estimate
H20: 0 | K20: 5000
A21: Site No. | B21: Category | C21: Location (Use map location, address, etc.): | G21: CR-1190 (Site 1) | L21: GPS
A22: 2 | B22: C | L22: 32.111477
L23: -97.494183
A24: Description Of Damage
A25: Chip and Seal roadway deteriorating after water sat on roadway for 12-21 days.
A29: Impact: | B29: Minor | H29: % Complete | K29: Cost Estimate
H30: 0 | K30: 25000
A31: Site No. | B31: Category | C31: Location (Use map location, address, etc.): | G31: CR-1190 (Site 2) | L31: GPS
A32: 3 | B32: C | L32: 31.078793
L33: -97.504822
A34: Description Of Damage
A35: Chip and Seal roadway deteriorating after water sat on roadway for 12-21 days.
A39: Impact: | B39: Minor | H39: % Complete | K39: Cost Estimate
H40: 0 | K40: 2000
A41: Site No. | B41: Category | C41: Location (Use map location, address, etc.): | G41: CR-3660 | L41: GPS
A42: 4 | B42: C | L42: 31.745107
L43: -97.298062
A44: Description Of Damage
A45: Bridge shoulder washed out. Note, Applicant is not claiming the debris. The 2 cmps and box culvert did not sustain any damage.
A49: Impact: | B49: Moderate | H49: % Complete | K49: Cost Estimate
H50: 0 | K50: 20000
A51: Name Of Inspector | D51: Agency | G51: Phone No. Office | K51: Phone No.CELL
A52: ='Summary Sheet'!E67 -> Vernon Lansford | D52: ='Summary Sheet'!G67 -> FEMA | K52: ='Summary Sheet'!I67 -> 225-910-5272
...

Sheet Bosque Co (2)
A1: Federal Emergency Management Agency | L1: Date
A2: Preliminary Damage Assessment Site Estimate | L2: 42557
A3: Part 1 - Applicant Information
A4: County | C4: Name Of Applicant | G4: Name Of Local Contact | L4: Contact Phone #
A5: Bosque | C5: Bosque County | G5: Tim Jeske | L5: 254-230-6622
A6: Part 2 - Site Information
A7: Key For Damage Category (Use appropriate letters in the "category" blocks below)
B8: a. Debris Removal | E8: d. Water Control Facilities | I8: g. Other Recreation
B9: b. Protective Measures | E9: e. Public Buildings
B10: c. Roads And Bridges | E10: f. Public Utilities
A11: Site No. | B11: Category | C11: Location (Use map location, address, etc.): | G11: ROADS | L11: GPS | O11: * NEEDS MITIGATION
A12: 5 | B12: C | L12: 31.820868
L13: -97.486504
A14: Description Of Damage
A15: Low water crossing undermined during the event.
A19: Impact: | B19: Minor, inconvenience and hazard to motorist | H19: % Complete | K19: Cost Estimate
H20: 0 | K20: 28000
A21: Site No. | B21: Category | C21: Location (Use map location, address, etc.): | L21: GPS
A24: Description Of Damage
A29: Impact: | H29: % Complete | K29: Cost Estimate
A31: Site No. | B31: Category | C31: Location (Use map location, address, etc.): | L31: GPS
A34: Description Of Damage
A39: Impact: | H39: % Complete | K39: Cost Estimate
A41: Site No. | B41: Category | C41: Location (Use map location, address, etc.): | L41: GPS
A44: Description Of Damage
A49: Impact: | H49: % Complete | K49: Cost Estimate
A51: Name Of Inspector | D51: Agency | G51: Phone No. Office | K51: Phone No.CELL
A52: ='Summary Sheet'!E67 -> Vernon Lansford | D52: ='Summary Sheet'!G67 -> FEMA | G52: =IF('Bosque Co'!G52=0,"",'Bosque Co'!G52) | K52: ='Summary Sheet'!I67 -> 225-910-5272
A54: FEMA Form 90-81, Jan 84 | G54: GRAND TOTAL SHEET 2 | K54: =+K20+K30+K40+K50 -> 28000
A56: 1. Asphalt (3100) $5.30/SY/IN | D56: 8. Grading Roads (3072) $0.10/SY | G56: 15. CMP 48" (3358) $62/LF | K56: 22. Auto Police (8073) $14.35/HR
A57: 2. Aggregate Surface (3011) $13/CY | D57: 9. Rip Rap (3250) $35/CY | G57: 16. CMP 60" (3354) $76/LF | K57: 23. CMD Center (9999) $339/HR
A58: 3. Aggregate Base (3091) $19.50/CY | D58: 10. Bridge Railing 3" (3294) $35/LF | G58: 17. CMP 72" (3354) $115/LF | K58: 24. Helo, Rescue (9999) $6277/HR
A59: 4. Chip & Seal Single (3080) $1.55/SY | D59: 11. Debris C&D (1012) $3.50/CY | G59: 18. CMP 120" (3364) $175/LF | K59: 25. Boat RBS (9999) $323/HR
A60: 5. Chip & Seal Double (3081) $2.79/SY | D60: 12. Debris Veg. (1015) $6/CY | G60: 19. Pickup (8804) $19.90/HR | K60: 26. Boat Utility (9999) $980/HR
A61: 6. Chip & Seal Triple (3082) $4.03/SY | D61: 13. CMP 24" (3354) $30/LF | G61: 20. Trailer, 30 T (8600) $9.90/HR | K61: 27. Person, Vol. (9999) $10/HR
A62: 7. Fill Unclas (3020) $7/CY | D62: 14. CMP 36" (3354) $41/LF | G62: 21. Bus, Large (8182) $30.00/HR | K62: 28. Canine & Handler (9999) $30/HR

Sheet Clifton
A1: Federal Emergency Management Agency | L1: Date
A2: Preliminary Damage Assessment Site Estimate | L2: 42557
A3: Part 1 - Applicant Information
A4: County | C4: Name Of Applicant | G4: Name Of Local Contact | L4: Contact Phone #
A5: Bosque | C5: City of Clifton | G5: Ashley Able | L5: 254-675-8337
A6: Part 2 - Site Information
A7: Key For Damage Category (Use appropriate letters in the "category" blocks below)
B8: a. Debris Removal | E8: d. Water Control Facilities | I8: g. Other Recreation
B9: b. Protective Measures | E9: e. Public Buildings
B10: c. Roads And Bridges | E10: f. Public Utilities
A11: Site No. | B11: Category | C11: Location (Use map location, address, etc.): | G11: Mountain Oak Circle | L11: GPS
A12: 1 | B12: C | L12: 31.77587
L13: -97.59748
A14: Description Of Damage
A15: Additional loss of asphalt and road base from event. Site previously damaged.
A19: Impact: | B19: Barricaded | H19: % Complete | K19: Cost Estimate
H20: 0 | K20: 28435
A21: Site No. | B21: Category | C21: Location (Use map location, address, etc.): | G21: White St starting at Ridgeview, South | L21: GPS
A22: 2 | B22: C | L22: 31.77634
L23: -97.59644
A24: Description Of Damage
A25: Additional loss of asphalt and road base from event. Site previously damaged.
A29: Impact: | B29: Minor inconvenience to motorist, base material only. | H29: % Complete | K29: Cost Estimate
H30: 0 | K30: 32500 | O30: =3500/700 -> 5 | P30: =O30*(7200-700) -> 32500
A31: Site No. | B31: Category | C31: Location (Use map location, address, etc.): | G31: 13th St | L31: GPS
A32: 3 | B32: C | L32: 31.77583
L33: -97.58194
A34: Description Of Damage
A35: Additional loss of asphalt and road base from event. Site previously damaged.
A39: Impact: | B39: Minor inconvenience to motorist, base material only. | H39: % Complete | K39: Cost Estimate
H40: 0 | K40: =17365-14875 -> 2490
A41: Site No. | B41: Category | C41: Location (Use map location, address, etc.): | G41: 21st St | L41: GPS
A42: 4 | B42: C | L42: 31.77139
L43: -97.58056
A44: Description Of Damage
A45: Additional damage to road base from event. Alligator cracking where there were none from earlier events. Road base very soft, Heavy vehicles have fallen through. Site previously damaged.
A49: Impact: | B49: Minor inconvenience to motorist, base material only. | H49: % Complete | K49: Cost Estimate
H50: 0 | K50: 22500
A51: Name Of Inspector | D51: Agency | G51: Phone No. Office | K51: Phone No.CELL
A52: ='Summary Sheet'!E67 -> Vernon Lansford | D52: ='Summary Sheet'!G67 -> FEMA | G52: =IF('Bosque Co'!G52=0,"",'Bosque Co'!G52) | K52: ='Summary Sheet'!I67 -> 225-910-5272
...

Sheet Clifton(2)
A1: Federal Emergency Management Agency | L1: Date
A2: Preliminary Damage Assessment Site Estimate | L2: 42557
A3: Part 1 - Applicant Information
A4: County | C4: Name Of Applicant | G4: Name Of Local Contact | L4: Contact Phone #
A5: Bosque | C5: City of Clifton | G5: Ashley Able | L5: 254-675-8337
A6: Part 2 - Site Information
A7: Key For Damage Category (Use appropriate letters in the "category" blocks below)
B8: a. Debris Removal | E8: d. Water Control Facilities | I8: g. Other Recreation
B9: b. Protective Measures | E9: e. Public Buildings
B10: c. Roads And Bridges | E10: f. Public Utilities
A11: Site No. | B11: Category | C11: Location (Use map location, address, etc.): | G11: Dam/Weir complex | L11: GPS | O11: * NEEDS MITIGATION
A12: 5 | B12: D | C12: On Bosque River off of CR-3112 | L12: 31.79478
L13: -97.57643
A14: Description Of Damage
A15: Additional erosion of complex and loss of Large Rip Rap from the event. Site damaged in Dr-4245-TX & Dr-4269-TX.
A19: Impact: | B19: High | H19: % Complete | K19: Cost Estimate
H20: 0 | K20: =104500-82000 -> 22500
A21: Site No. | B21: Category | C21: Location (Use map location, address, etc.): | L21: GPS
A24: Description Of Damage
A29: Impact: | H29: % Complete | K29: Cost Estimate
A31: Site No. | B31: Category | C31: Location (Use map location, address, etc.): | L31: GPS
A34: Description Of Damage
A39: Impact: | H39: % Complete | K39: Cost Estimate
A41: Site No. | B41: Category | C41: Location (Use map location, address, etc.): | L41: GPS
A44: Description Of Damage
A49: Impact: | H49: % Complete | K49: Cost Estimate
A51: Name Of Inspector | D51: Agency | G51: Phone No. Office | K51: Phone No.CELL
A52: ='Summary Sheet'!E67 -> Vernon Lansford | D52: ='Summary Sheet'!G67 -> FEMA | G52: =IF('Bosque Co'!G52=0,"",'Bosque Co'!G52) | K52: ='Summary Sheet'!I67 -> 225-910-5272
A54: FEMA Form 90-81, Jan 84 | G54: GRAND TOTAL SHEET 2 | K54: =+K20+K30+K40+K50 -> 22500
A56: 1. Asphalt (3100) $5.30/SY/IN | D56: 8. Grading Roads (3072) $0.10/SY | G56: 15. CMP 48" (3358) $62/LF | K56: 22. Auto Police (8073) $14.35/HR
A57: 2. Aggregate Surface (3011) $13/CY | D57: 9. Rip Rap (3250) $35/CY | G57: 16. CMP 60" (3354) $76/LF | K57: 23. CMD Center (9999) $339/HR
A58: 3. Aggregate Base (3091) $19.50/CY | D58: 10. Bridge Railing 3" (3294) $35/LF | G58: 17. CMP 72" (3354) $115/LF | K58: 24. Helo, Rescue (9999) $6277/HR
A59: 4. Chip & Seal Single (3080) $1.55/SY | D59: 11. Debris C&D (1012) $3.50/CY | G59: 18. CMP 120" (3364) $175/LF | K59: 25. Boat RBS (9999) $323/HR
A60: 5. Chip & Seal Double (3081) $2.79/SY | D60: 12. Debris Veg. (1015) $6/CY | G60: 19. Pickup (8804) $19.90/HR | K60: 26. Boat Utility (9999) $980/HR
A61: 6. Chip & Seal Triple (3082) $4.03/SY | D61: 13. CMP 24" (3354) $30/LF | G61: 20. Trailer, 30 T (8600) $9.90/HR | K61: 27. Person, Vol. (9999) $10/HR
A62: 7. Fill Unclas (3020) $7/CY | D62: 14. CMP 36" (3354) $41/LF | G62: 21. Bus, Large (8182) $30.00/HR | K62: 28. Canine & Handler (9999) $30/HR

Sheet Valley Mills
A1: Federal Emergency Management Agency | L1: Date
A2: Preliminary Damage Assessment Site Estimate
A3: Part 1 - Applicant Information
A4: County | C4: Name Of Applicant | G4: Name Of Local Contact | L4: Contact Phone #
A5: Bosque | C5: City of Valley Mills
A6: Part 2 - Site Information
A7: Key For Damage Category (Use appropriate letters in the "category" blocks below)
B8: a. Debris Removal | E8: d. Water Control Facilities | I8: g. Other Recreation
B9: b. Protective Measures | E9: e. Public Buildings
B10: c. Roads And Bridges | E10: f. Public Utilities
A11: Site No. | B11: Category | C11: Location (Use map location, address, etc.): | G11: Staging Site | L11: GPS | O11: * NEEDS MITIGATION
A12: 1 | B12: A | C12: North end of 2nd Street | L12: 31.65111
L13: -97.47799
A14: Description Of Damage
A15: Debris collected from Storm Event. Applicant has minimal means of picking up and removing debris, thus cost will be on the higher side. Estimated stack with 100 CY with more to be added.
A19: Impact: | B19: Minor | H19: % Complete | K19: Cost Estimate
H20: 75 | K20: 3080
A21: Site No. | B21: Category | C21: Location (Use map location, address, etc.): | L21: GPS
A24: Description Of Damage
A29: Impact: | H29: % Complete | K29: Cost Estimate
A31: Site No. | B31: Category | C31: Location (Use map location, address, etc.): | L31: GPS
A34: Description Of Damage
A39: Impact: | H39: % Complete | K39: Cost Estimate
A41: Site No. | B41: Category | C41: Location (Use map location, address, etc.): | L41: GPS
A44: Description Of Damage
A49: Impact: | H49: % Complete | K49: Cost Estimate
A51: Name Of Inspector | D51: Agency | G51: Phone No. Office | K51: Phone No.CELL
A52: ='Summary Sheet'!E67 -> Vernon Lansford | D52: ='Summary Sheet'!G67 -> FEMA | G52: =IF('Bosque Co'!G52=0,"",'Bosque Co'!G52) | K52: ='Summary Sheet'!I67 -> 225-910-5272
A54: FEMA Form 90-81, Jan 84 | G54: GRAND TOTAL SHEET 2 | K54: =+K20+K30+K40+K50 -> 3080
A56: 1. Asphalt (3100) $5.30/SY/IN | D56: 8. Grading Roads (3072) $0.10/SY | G56: 15. CMP 48" (3358) $62/LF | K56: 22. Auto Police (8073) $14.35/HR
A57: 2. Aggregate Surface (3011) $13/CY | D57: 9. Rip Rap (3250) $35/CY | G57: 16. CMP 60" (3354) $76/LF | K57: 23. CMD Center (9999) $339/HR
A58: 3. Aggregate Base (3091) $19.50/CY | D58: 10. Bridge Railing 3" (3294) $35/LF | G58: 17. CMP 72" (3354) $115/LF | K58: 24. Helo, Rescue (9999) $6277/HR
A59: 4. Chip & Seal Single (3080) $1.55/SY | D59: 11. Debris C&D (1012) $3.50/CY | G59: 18. CMP 120" (3364) $175/LF | K59: 25. Boat RBS (9999) $323/HR
A60: 5. Chip & Seal Double (3081) $2.79/SY | D60: 12. Debris Veg. (1015) $6/CY | G60: 19. Pickup (8804) $19.90/HR | K60: 26. Boat Utility (9999) $980/HR
A61: 6. Chip & Seal Triple (3082) $4.03/SY | D61: 13. CMP 24" (3354) $30/LF | G61: 20. Trailer, 30 T (8600) $9.90/HR | K61: 27. Person, Vol. (9999) $10/HR
A62: 7. Fill Unclas (3020) $7/CY | D62: 14. CMP 36" (3354) $41/LF | G62: 21. Bus, Large (8182) $30.00/HR | K62: 28. Canine & Handler (9999) $30/HR

Sheet S6
A1: Federal Emergency Management Agency | L1: Date
A2: Preliminary Damage Assessment Site Estimate
A3: Part 1 - Applicant Information
A4: County | C4: Name Of Applicant | G4: Name Of Local Contact | L4: Contact Phone #
A6: Part 2 - Site Information
A7: Key For Damage Category (Use appropriate letters in the "category" blocks below)
B8: a. Debris Removal | E8: d. Water Control Facilities | I8: g. Other Recreation
B9: b. Protective Measures | E9: e. Public Buildings
B10: c. Roads And Bridges | E10: f. Public Utilities
A11: Site No. | B11: Category | C11: Location (Use map location, address, etc.): | L11: GPS | O11: * NEEDS MITIGATION
A14: Description Of Damage
A19: Impact: | H19: % Complete | K19: Cost Estimate
A21: Site No. | B21: Category | C21: Location (Use map location, address, etc.): | L21: GPS
A24: Description Of Damage
A29: Impact: | H29: % Complete | K29: Cost Estimate
A31: Site No. | B31: Category | C31: Location (Use map location, address, etc.): | L31: GPS
A34: Description Of Damage
A39: Impact: | H39: % Complete | K39: Cost Estimate
A41: Site No. | B41: Category | C41: Location (Use map location, address, etc.): | L41: GPS
A44: Description Of Damage
A49: Impact: | H49: % Complete | K49: Cost Estimate
A51: Name Of Inspector | D51: Agency | G51: Phone No. Office | K51: Phone No.CELL
A52: ='Summary Sheet'!E67 -> Vernon Lansford | D52: ='Summary Sheet'!G67 -> FEMA | G52: =IF('Bosque Co'!G52=0,"",'Bosque Co'!G52) | K52: ='Summary Sheet'!I67 -> 225-910-5272
A54: FEMA Form 90-81, Jan 84 | G54: GRAND TOTAL SHEET 2 | K54: =+K20+K30+K40+K50 -> 0
A56: 1. Asphalt (3100) $5.30/SY/IN | D56: 8. Grading Roads (3072) $0.10/SY | G56: 15. CMP 48" (3358) $62/LF | K56: 22. Auto Police (8073) $14.35/HR
A57: 2. Aggregate Surface (3011) $13/CY | D57: 9. Rip Rap (3250) $35/CY | G57: 16. CMP 60" (3354) $76/LF | K57: 23. CMD Center (9999) $339/HR
A58: 3. Aggregate Base (3091) $19.50/CY | D58: 10. Bridge Railing 3" (3294) $35/LF | G58: 17. CMP 72" (3354) $115/LF | K58: 24. Helo, Rescue (9999) $6277/HR
A59: 4. Chip & Seal Single (3080) $1.55/SY | D59: 11. Debris C&D (1012) $3.50/CY | G59: 18. CMP 120" (3364) $175/LF | K59: 25. Boat RBS (9999) $323/HR
A60: 5. Chip & Seal Double (3081) $2.79/SY | D60: 12. Debris Veg. (1015) $6/CY | G60: 19. Pickup (8804) $19.90/HR | K60: 26. Boat Utility (9999) $980/HR
A61: 6. Chip & Seal Triple (3082) $4.03/SY | D61: 13. CMP 24" (3354) $30/LF | G61: 20. Trailer, 30 T (8600) $9.90/HR | K61: 27. Person, Vol. (9999) $10/HR
A62: 7. Fill Unclas (3020) $7/CY | D62: 14. CMP 36" (3354) $41/LF | G62: 21. Bus, Large (8182) $30.00/HR | K62: 28. Canine & Handler (9999) $30/HR

Sheet Time Calc
A1: =TEXT(B1, "dddd") -> Tuesday | B1: 41618.635 | C1: Through | D1: =TEXT(E1, "dddd") -> Tuesday | E1: 41618.75 | F1: =SUM(E1-B1)*24 -> 2.7644444
A2: =TEXT(B2, "dddd") -> Friday | B2: 41621.49 | C2: Through | D2: =TEXT(E2, "dddd") -> Saturday | E2: 41622.083 | F2: =SUM(E2-B2)*24 -> 14.233333
A3: =TEXT(B3, "dddd") -> Tuesday | B3: 41275.5 | C3: Through | D3: =TEXT(E3, "dddd") -> Tuesday | E3: 41275.5 | F3: =SUM(E3-B3)*24 -> 0
A4: =TEXT(B4, "dddd") -> Tuesday | B4: 41275.5 | C4: Through | D4: =TEXT(E4, "dddd") -> Tuesday | E4: 41275.5 | F4: =SUM(E4-B4)*24 -> 0
A5: =TEXT(B5, "dddd") -> Tuesday | B5: 41275.5 | C5: Through | D5: =TEXT(E5, "dddd") -> Tuesday | E5: 41275.5 | F5: =SUM(E5-B5)*24 -> 0
A6: =TEXT(B6, "dddd") -> Tuesday | B6: 41275.5 | C6: Through | D6: =TEXT(E6, "dddd") -> Tuesday | E6: 41275.5 | F6: =SUM(E6-B6)*24 -> 0
A7: =TEXT(B7, "dddd") -> Tuesday | B7: 41275.5 | C7: Through | D7: =TEXT(E7, "dddd") -> Tuesday | E7: 41275.5 | F7: =SUM(E7-B7)*24 -> 0
A8: =TEXT(B8, "dddd") -> Tuesday | B8: 41275.5 | C8: Through | D8: =TEXT(E8, "dddd") -> Tuesday | E8: 41275.5 | F8: =SUM(E8-B8)*24 -> 0
A9: =TEXT(B9, "dddd") -> Tuesday | B9: 41275.5 | C9: Through | D9: =TEXT(E9, "dddd") -> Tuesday | E9: 41275.5 | F9: =SUM(E9-B9)*24 -> 0
A10: =TEXT(B10, "dddd") -> Tuesday | B10: 41275.5 | C10: Through | D10: =TEXT(E10, "dddd") -> Tuesday | E10: 41275.5 | F10: =SUM(E10-B10)*24 -> 0
A11: =TEXT(B11, "dddd") -> Tuesday | B11: 41275.5 | C11: Through | D11: =TEXT(E11, "dddd") -> Tuesday | E11: 41275.5 | F11: =SUM(E11-B11)*24 -> 0
A12: =TEXT(B12, "dddd") -> Tuesday | B12: 41275.5 | C12: Through | D12: =TEXT(E12, "dddd") -> Tuesday | E12: 41275.5 | F12: =SUM(E12-B12)*24 -> 0
... A46: =TEXT(B46, "dddd") -> Thursday | B46: 41298.5 | C46: Through | D46: =TEXT(E46, "dddd") -> Thursday | E46: 41298.5 | F46: =SUM(E46-B46)*24 -> 0
F48: =SUM(F1:F46) -> 16.997778

Sheet FEMAcostcodes
A1: femacode | B1: Insert the date the cost codes were updated: | F1: 40436
A2: Cost Code | B2: Cost Code Description | C2: Unit | D2: Unit Price | E2: Detailed Description | F2: HP | G2: Capacity | H2: Date Updated
A3: cost_cd | B3: cd_desc | C3: uom | D3: unit_price | E3: dtl_desc
A4: 0000 | B4: WORK COMPLETED | C4: LS | D4: $ 0.00 | H4: 39462 | I4: =IF(B4="","",B4) -> WORK COMPLETED
A5: 0000 | B5: WORK TO BE COMPLETED | C5: LS | D5: $ 0.00 | H5: 39462 | I5: =IF(B5="","",B5) -> WORK TO BE COMPLETED
A6: 0909 | B6: MITIGATION | C6: LS | D6: $ 0.00 | E6: 406 MITIGATION | H6: 39462 | I6: =IF(B6="","",B6) -> MITIGATION
A7: 9000 | B7: CEF COST ESTIMATE | C7: LS | D7: $ 0.00 | E7: CEF COST ESTIMATE | H7: 39462 | I7: =IF(B7="","",B7) -> CEF COST ESTIMATE
A8: 9001 | B8: CONTRACT | C8: LS | D8: $ 0.00 | E8: CONTRACT | H8: 39462 | I8: =IF(B8="","",B8) -> CONTRACT
A9: 9003 | B9: CONTRACT COSTS | C9: LS | D9: $ 0.00 | E9: CONTRACT COSTS | H9: 39462 | I9: =IF(B9="","",B9) -> CONTRACT COSTS
A10: 9004 | B10: RENTED EQUIPMENT | C10: LS | D10: $ 0.00 | E10: RENTED EQUIPMENT | H10: 39462 | I10: =IF(B10="","",B10) -> RENTED EQUIPMENT
A11: 9005 | B11: LABOR, O/T W/O BENEFITS | C11: LS | D11: $ 0.00 | E11: LABOR, O/T W/O BENEFITS | H11: 39462 | I11: =IF(B11="","",B11) -> LABOR, O/T W/O BENEFITS
A12: 9006 | B12: LABOR, W/O BENEFITS | C12: LS | D12: $ 0.00 | E12: LABOR, W/O BENEFITS | H12: 39462 | I12: =IF(B12="","",B12) -> LABOR, W/O BENEFITS
A13: 9007 | B13: LABOR | C13: LS | D13: $ 0.00 | E13: LABOR | H13: 39462 | I13: =IF(B13="","",B13) -> LABOR
A14: 9008 | B14: EQUIPMENT | C14: LS | D14: $ 0.00 | E14: EQUIPMENT | H14: 39462 | I14: =IF(B14="","",B14) -> EQUIPMENT
A15: 9009 | B15: MATERIAL | C15: LS | D15: $ 0.00 | E15: MATERIAL | H15: 39462 | I15: =IF(B15="","",B15) -> MATERIAL
A16: 9010 | B16: LABORER REGULAR TIME | C16: HR | D16: $ 0.00 | E16: LABORER REGULAR TIME | H16: 39462 | I16: =IF(B16="","",B16) -> LABORER REGULAR TIME
A17: 9011 | B17: LABORER OVERTIME | C17: HR | D17: $ 0.00 | E17: LABORER OVERTIME | H17: 39462 | I17: =IF(B17="","",B17) -> LABORER OVERTIME
A18: 9012 | B18: EQUIPMENT OPERATOR REGULAR TIME | C18: HR | D18: $ 0.00 | E18: EQUIPMENT OPERATOR REGULAR TIME | H18: 39462 | I18: =IF(B18="","",B18) -> EQUIPMENT OPERATOR REGULAR TIME
... A35: 5905 | B35: DEDUCT ANTICIPATED FLOOD INSURANCE PROCEEDS - LS | C35: LS | D35: $ 0.00 | E35: DEDUCT ANTICIPATED FLOOD INSURANCE PROCEEDS | H35: 39462 | I35: =IF(B35="","",B35) -> DEDUCT ANTICIPATED FLOOD INSURANCE PROCEEDS - LS
I36: =IF(B36="","",B36)
A37: 0000 | B37: Work Completed | C37: LS | D37: 0 | H37: 39645 | I37: =IF(B37="","",B37) -> Work Completed
A38: 0000 | B38: Work to be Completed | C38: LS | D38: 0 | H38: 39645 | I38: =IF(B38="","",B38) -> Work to be Completed
A39: 0909 | B39: MITIGATION | C39: LS | D39: 0 | H39: 39645 | I39: =IF(B39="","",B39) -> MITIGATION
A40: 1001 | B40: DEBRIS (SEDIMENTS, CONCENTRATED) | C40: TON | D40: 0 | H40: 39645 | I40: =IF(B40="","",B40) -> DEBRIS (SEDIMENTS, CONCENTRATED)
A41: 1002 | B41: DEBRIS (SEDIMENTS, SCATTERED) | C41: TON | D41: 0 | H41: 39645 | I41: =IF(B41="","",B41) -> DEBRIS (SEDIMENTS, SCATTERED)
A42: 1003 | B42: DEBRIS (Personal Property Curb) | C42: TON | D42: 0 | H42: 39645 | I42: =IF(B42="","",B42) -> DEBRIS (Personal Property Curb)
A43: 1004 | B43: DEBRIS (TREES & LIMBS, CONCENTRATED) | C43: TON | D43: 0 | H43: 39645 | I43: =IF(B43="","",B43) -> DEBRIS (TREES & LIMBS, CONCENTRATED)
A44: 1005 | B44: DEBRIS (TREES & LIMBS, SCATTERED) | C44: TON | D44: 0 | H44: 39644 | I44: =IF(B44="","",B44) -> DEBRIS (TREES & LIMBS, SCATTERED)
A45: 1010 | B45: DEBRIS (SEDIMENTS, CONCENTRATED) | C45: CY | D45: 3.3 | H45: 39869 | I45: =IF(B45="","",B45) -> DEBRIS (SEDIMENTS, CONCENTRATED)
A46: 1011 | B46: DEBRIS (SEDIMENTS, SCATTERED) | C46: CY | D46: 4 | H46: 39869 | I46: =IF(B46="","",B46) -> DEBRIS (SEDIMENTS, SCATTERED)
A47: 1012 | B47: DEBRIS (Personal Property Curb) | C47: CY | D47: 3.5 | H47: 39552 | I47: =IF(B47="","",B47) -> DEBRIS (Personal Property Curb)
A48: 1014 | B48: DEBRIS (TREES & LIMBS, CONCENTRATED) | C48: CY | D48: 4 | H48: 39552 | I48: =IF(B48="","",B48) -> DEBRIS (TREES & LIMBS, CONCENTRATED)
... A60: 1041 | B60: DEBRIS STUMPS REMOVAL (UPROOTED 19" - 36" DIAMETER) | C60: CY | D60: 32 | H60: 40878 | I60: =IF(B60="","",B60) -> DEBRIS STUMPS REMOVAL (UPROOTED 19" - 36" DIAMETER)
A61: 1042 | B61: DEBRIS STUMPS REMOVAL (UPROOTED 37" DIAMETER AND OVER) | C61: CY | D61: 36 | H61: NIN | I61: =IF(B61="","",B61) -> DEBRIS STUMPS REMOVAL (UPROOTED 37" DIAMETER AND OVER)
A62: 1043 | B62: DEBRIS STUMPS REMOVAL (UPROOTED 24"-36" DIAMETER) | C62: EA | D62: 200 | H62: 39869 | I62: =IF(B62="","",B62) -> DEBRIS STUMPS REMOVAL (UPROOTED 24"-36" DIAMETER)
A63: 1044 | B63: DEBRIS STUMPS REMOVAL (UPROOTED 37" DIAMETER AND OVER) | C63: EA | D63: 250 | H63: 39869 | I63: =IF(B63="","",B63) -> DEBRIS STUMPS REMOVAL (UPROOTED 37" DIAMETER AND OVER)
A64: 1050 | B64: DUMP CHARGES (BURN - BURY) | C64: CY | D64: 1 | H64: 39552 | I64: =IF(B64="","",B64) -> DUMP CHARGES (BURN - BURY)
A65: 1051 | B65: DUMP CHARGES (LANDFILL DISPOSAL) | C65: CY | D65: 1.75 | H65: 39552 | I65: =IF(B65="","",B65) -> DUMP CHARGES (LANDFILL DISPOSAL)
A66: 1052 | B66: DUMP CHARGES (LANDFILL DISPOSAL) | C66: TON | D66: 4 | H66: 39624 | I66: =IF(B66="","",B66) -> DUMP CHARGES (LANDFILL DISPOSAL)
A67: 1060 | B67: DEBRIS CONTAINERS (W/0 DUMP CHARGES) 2 CY PER PICKUP | C67: EA | D67: 5 | H67: 39552 | I67: =IF(B67="","",B67) -> DEBRIS CONTAINERS (W/0 DUMP CHARGES) 2 CY PER PICKUP
...
